//[example_output
> example
Running 1 test case...
test.cpp(10): error in "test": exception thrown by throw my_exception()

*** 1 failures is detected in test suite "example"
//]